2021-06-02 15:06:59,432 [INFO]: #  From Excel import testsuite success
2021-06-02 15:07:08,629 [ERROR]: #  *** Init global object failure ***
Traceback (most recent call last):
  File "D:\Program Files\Python38\lib\site-packages\urllib3\connection.py", line 169, in _new_conn
    conn = connection.create_connection(
  File "D:\Program Files\Python38\lib\site-packages\urllib3\util\connection.py", line 96, in create_connection
    raise err
  File "D:\Program Files\Python38\lib\site-packages\urllib3\util\connection.py", line 86, in create_connection
    sock.connect(sa)
ConnectionRefusedError: [WinError 10061] 由于目标计算机积极拒绝，无法连接。

During handling of the above exception, another exception occurred:

Traceback (most recent call last):
  File "D:\Program Files\Python38\lib\site-packages\urllib3\connectionpool.py", line 699, in urlopen
    httplib_response = self._make_request(
  File "D:\Program Files\Python38\lib\site-packages\urllib3\connectionpool.py", line 394, in _make_request
    conn.request(method, url, **httplib_request_kw)
  File "D:\Program Files\Python38\lib\site-packages\urllib3\connection.py", line 234, in request
    super(HTTPConnection, self).request(method, url, body=body, headers=headers)
  File "D:\Program Files\Python38\lib\http\client.py", line 1252, in request
    self._send_request(method, url, body, headers, encode_chunked)
  File "D:\Program Files\Python38\lib\http\client.py", line 1298, in _send_request
    self.endheaders(body, encode_chunked=encode_chunked)
  File "D:\Program Files\Python38\lib\http\client.py", line 1247, in endheaders
    self._send_output(message_body, encode_chunked=encode_chunked)
  File "D:\Program Files\Python38\lib\http\client.py", line 1007, in _send_output
    self.send(msg)
  File "D:\Program Files\Python38\lib\http\client.py", line 947, in send
    self.connect()
  File "D:\Program Files\Python38\lib\site-packages\urllib3\connection.py", line 200, in connect
    conn = self._new_conn()
  File "D:\Program Files\Python38\lib\site-packages\urllib3\connection.py", line 181, in _new_conn
    raise NewConnectionError(
urllib3.exceptions.NewConnectionError: <urllib3.connection.HTTPConnection object at 0x00000225777BC520>: Failed to establish a new connection: [WinError 10061] 由于目标计算机积极拒绝，无法连接。

During handling of the above exception, another exception occurred:

Traceback (most recent call last):
  File "D:\Program Files\Python38\lib\site-packages\sweetest\autotest.py", line 105, in run
    g.set_driver()
  File "D:\Program Files\Python38\lib\site-packages\sweetest\globals.py", line 122, in set_driver
    self.driver = appdriver.Remote(self.server_url, self.desired_caps)
  File "D:\Program Files\Python38\lib\site-packages\appium\webdriver\webdriver.py", line 155, in __init__
    super().__init__(
  File "D:\Program Files\Python38\lib\site-packages\selenium\webdriver\remote\webdriver.py", line 157, in __init__
    self.start_session(capabilities, browser_profile)
  File "D:\Program Files\Python38\lib\site-packages\appium\webdriver\webdriver.py", line 225, in start_session
    response = self.execute(RemoteCommand.NEW_SESSION, parameters)
  File "D:\Program Files\Python38\lib\site-packages\selenium\webdriver\remote\webdriver.py", line 319, in execute
    response = self.command_executor.execute(driver_command, params)
  File "D:\Program Files\Python38\lib\site-packages\selenium\webdriver\remote\remote_connection.py", line 374, in execute
    return self._request(command_info[0], url, body=data)
  File "D:\Program Files\Python38\lib\site-packages\selenium\webdriver\remote\remote_connection.py", line 397, in _request
    resp = self._conn.request(method, url, body=body, headers=headers)
  File "D:\Program Files\Python38\lib\site-packages\urllib3\request.py", line 78, in request
    return self.request_encode_body(
  File "D:\Program Files\Python38\lib\site-packages\urllib3\request.py", line 170, in request_encode_body
    return self.urlopen(method, url, **extra_kw)
  File "D:\Program Files\Python38\lib\site-packages\urllib3\poolmanager.py", line 375, in urlopen
    response = conn.urlopen(method, u.request_uri, **kw)
  File "D:\Program Files\Python38\lib\site-packages\urllib3\connectionpool.py", line 783, in urlopen
    return self.urlopen(
  File "D:\Program Files\Python38\lib\site-packages\urllib3\connectionpool.py", line 783, in urlopen
    return self.urlopen(
  File "D:\Program Files\Python38\lib\site-packages\urllib3\connectionpool.py", line 783, in urlopen
    return self.urlopen(
  File "D:\Program Files\Python38\lib\site-packages\urllib3\connectionpool.py", line 755, in urlopen
    retries = retries.increment(
  File "D:\Program Files\Python38\lib\site-packages\urllib3\util\retry.py", line 574, in increment
    raise MaxRetryError(_pool, url, error or ResponseError(cause))
urllib3.exceptions.MaxRetryError: HTTPConnectionPool(host='127.0.0.1', port=4723): Max retries exceeded with url: /wd/hub/session (Caused by NewConnectionError('<urllib3.connection.HTTPConnection object at 0x00000225777BC520>: Failed to establish a new connection: [WinError 10061] 由于目标计算机积极拒绝，无法连接。'))
